Workbook

Sheet Raw_Data
A1: Serial_Number | B1: survived | C1: pclass | D1: sex | E1: age | F1: sibsp | G1: parch | H1: fare | I1: embarked | J1: class | K1: who | L1: adult_male | M1: deck | N1: embark_town | O1: alive | P1: alone
A2: 1 | B2: 0 | C2: 3 | D2: male | E2: 22 | F2: 1 | G2: 0 | H2: 7.25 | I2: S | J2: Third | K2: man | L2: TRUE | N2: Southampton | O2: no | P2: FALSE
A3: 2 | B3: 1 | C3: 1 | D3: female | E3: 38 | F3: 1 | G3: 0 | H3: 71.2833 | I3: C | J3: First | K3: woman | L3: FALSE | M3: C | N3: Cherbourg | O3: yes | P3: FALSE
A4: 3 | B4: 1 | C4: 3 | D4: female | E4: 26 | F4: 0 | G4: 0 | H4: 7.925 | I4: S | J4: Third | K4: woman | L4: FALSE | N4: Southampton | O4: yes | P4: TRUE
A5: 4 | B5: 1 | C5: 1 | D5: female | E5: 35 | F5: 1 | G5: 0 | H5: 53.1 | I5: S | J5: First | K5: woman | L5: FALSE | M5: C | N5: Southampton | O5: yes | P5: FALSE
A6: 5 | B6: 0 | C6: 3 | D6: male | E6: 35 | F6: 0 | G6: 0 | H6: 8.05 | I6: S | J6: Third | K6: man | L6: TRUE | N6: Southampton | O6: no | P6: TRUE
A7: 6 | B7: 0 | C7: 3 | D7: male | F7: 0 | G7: 0 | H7: 8.4583 | I7: Q | J7: Third | K7: man | L7: TRUE | N7: Queenstown | O7: no | P7: TRUE
A8: 7 | B8: 0 | C8: 1 | D8: male | E8: 54 | F8: 0 | G8: 0 | H8: 51.8625 | I8: S | J8: First | K8: man | L8: TRUE | M8: E | N8: Southampton | O8: no | P8: TRUE
A9: 8 | B9: 0 | C9: 3 | D9: male | E9: 2 | F9: 3 | G9: 1 | H9: 21.075 | I9: S | J9: Third | K9: child | L9: FALSE | N9: Southampton | O9: no | P9: FALSE
A10: 9 | B10: 1 | C10: 3 | D10: female | E10: 27 | F10: 0 | G10: 2 | H10: 11.1333 | I10: S | J10: Third | K10: woman | L10: FALSE | N10: Southampton | O10: yes | P10: FALSE
A11: 10 | B11: 1 | C11: 2 | D11: female | E11: 14 | F11: 1 | G11: 0 | H11: 30.0708 | I11: C | J11: Second | K11: child | L11: FALSE | N11: Cherbourg | O11: yes | P11: FALSE
A12: 11 | B12: 1 | C12: 3 | D12: female | E12: 4 | F12: 1 | G12: 1 | H12: 16.7 | I12: S | J12: Third | K12: child | L12: FALSE | M12: G | N12: Southampton | O12: yes | P12: FALSE
A13: 12 | B13: 1 | C13: 1 | D13: female | E13: 58 | F13: 0 | G13: 0 | H13: 26.55 | I13: S | J13: First | K13: woman | L13: FALSE | M13: C | N13: Southampton | O13: yes | P13: TRUE
A14: 13 | B14: 0 | C14: 3 | D14: male | E14: 20 | F14: 0 | G14: 0 | H14: 8.05 | I14: S | J14: Third | K14: man | L14: TRUE | N14: Southampton | O14: no | P14: TRUE
A15: 14 | B15: 0 | C15: 3 | D15: male | E15: 39 | F15: 1 | G15: 5 | H15: 31.275 | I15: S | J15: Third | K15: man | L15: TRUE | N15: Southampton | O15: no | P15: FALSE
A16: 15 | B16: 0 | C16: 3 | D16: female | E16: 14 | F16: 0 | G16: 0 | H16: 7.8542 | I16: S | J16: Third | K16: child | L16: FALSE | N16: Southampton | O16: no | P16: TRUE
A17: 16 | B17: 1 | C17: 2 | D17: female | E17: 55 | F17: 0 | G17: 0 | H17: 16 | I17: S | J17: Second | K17: woman | L17: FALSE | N17: Southampton | O17: yes | P17: TRUE
A18: 17 | B18: 0 | C18: 3 | D18: male | E18: 2 | F18: 4 | G18: 1 | H18: 29.125 | I18: Q | J18: Third | K18: child | L18: FALSE | N18: Queenstown | O18: no | P18: FALSE
A19: 18 | B19: 1 | C19: 2 | D19: male | F19: 0 | G19: 0 | H19: 13 | I19: S | J19: Second | K19: man | L19: TRUE | N19: Southampton | O19: yes | P19: TRUE
A20: 19 | B20: 0 | C20: 3 | D20: female | E20: 31 | F20: 1 | G20: 0 | H20: 18 | I20: S | J20: Third | K20: woman | L20: FALSE | N20: Southampton | O20: no | P20: FALSE
A21: 20 | B21: 1 | C21: 3 | D21: female | F21: 0 | G21: 0 | H21: 7.225 | I21: C | J21: Third | K21: woman | L21: FALSE | N21: Cherbourg | O21: yes | P21: TRUE
A22: 21 | B22: 0 | C22: 2 | D22: male | E22: 35 | F22: 0 | G22: 0 | H22: 26 | I22: S | J22: Second | K22: man | L22: TRUE | N22: Southampton | O22: no | P22: TRUE
A23: 22 | B23: 1 | C23: 2 | D23: male | E23: 34 | F23: 0 | G23: 0 | H23: 13 | I23: S | J23: Second | K23: man | L23: TRUE | M23: D | N23: Southampton | O23: yes | P23: TRUE
A24: 23 | B24: 1 | C24: 3 | D24: female | E24: 15 | F24: 0 | G24: 0 | H24: 8.0292 | I24: Q | J24: Third | K24: child | L24: FALSE | N24: Queenstown | O24: yes | P24: TRUE
A25: 24 | B25: 1 | C25: 1 | D25: male | E25: 28 | F25: 0 | G25: 0 | H25: 35.5 | I25: S | J25: First | K25: man | L25: TRUE | M25: A | N25: Southampton | O25: yes | P25: TRUE
A26: 25 | B26: 0 | C26: 3 | D26: female | E26: 8 | F26: 3 | G26: 1 | H26: 21.075 | I26: S | J26: Third | K26: child | L26: FALSE | N26: Southampton | O26: no | P26: FALSE
A27: 26 | B27: 1 | C27: 3 | D27: female | E27: 38 | F27: 1 | G27: 5 | H27: 31.3875 | I27: S | J27: Third | K27: woman | L27: FALSE | N27: Southampton | O27: yes | P27: FALSE
A28: 27 | B28: 0 | C28: 3 | D28: male | F28: 0 | G28: 0 | H28: 7.225 | I28: C | J28: Third | K28: man | L28: TRUE | N28: Cherbourg | O28: no | P28: TRUE
A29: 28 | B29: 0 | C29: 1 | D29: male | E29: 19 | F29: 3 | G29: 2 | H29: 263 | I29: S | J29: First | K29: man | L29: TRUE | M29: C | N29: Southampton | O29: no | P29: FALSE
A30: 29 | B30: 1 | C30: 3 | D30: female | F30: 0 | G30: 0 | H30: 7.8792 | I30: Q | J30: Third | K30: woman | L30: FALSE | N30: Queenstown | O30: yes | P30: TRUE
A31: 30 | B31: 0 | C31: 3 | D31: male | F31: 0 | G31: 0 | H31: 7.8958 | I31: S | J31: Third | K31: man | L31: TRUE | N31: Southampton | O31: no | P31: TRUE
A32: 31 | B32: 0 | C32: 1 | D32: male | E32: 40 | F32: 0 | G32: 0 | H32: 27.7208 | I32: C | J32: First | K32: man | L32: TRUE | N32: Cherbourg | O32: no | P32: TRUE
A33: 32 | B33: 1 | C33: 1 | D33: female | F33: 1 | G33: 0 | H33: 146.5208 | I33: C | J33: First | K33: woman | L33: FALSE | M33: B | N33: Cherbourg | O33: yes | P33: FALSE
A34: 33 | B34: 1 | C34: 3 | D34: female | F34: 0 | G34: 0 | H34: 7.75 | I34: Q | J34: Third | K34: woman | L34: FALSE | N34: Queenstown | O34: yes | P34: TRUE
A35: 34 | B35: 0 | C35: 2 | D35: male | E35: 66 | F35: 0 | G35: 0 | H35: 10.5 | I35: S | J35: Second | K35: man | L35: TRUE | N35: Southampton | O35: no | P35: TRUE
A36: 35 | B36: 0 | C36: 1 | D36: male | E36: 28 | F36: 1 | G36: 0 | H36: 82.1708 | I36: C | J36: First | K36: man | L36: TRUE | N36: Cherbourg | O36: no | P36: FALSE
A37: 36 | B37: 0 | C37: 1 | D37: male | E37: 42 | F37: 1 | G37: 0 | H37: 52 | I37: S | J37: First | K37: man | L37: TRUE | N37: Southampton | O37: no | P37: FALSE
A38: 37 | B38: 1 | C38: 3 | D38: male | F38: 0 | G38: 0 | H38: 7.2292 | I38: C | J38: Third | K38: man | L38: TRUE | N38: Cherbourg | O38: yes | P38: TRUE
A39: 38 | B39: 0 | C39: 3 | D39: male | E39: 21 | F39: 0 | G39: 0 | H39: 8.05 | I39: S | J39: Third | K39: man | L39: TRUE | N39: Southampton | O39: no | P39: TRUE
A40: 39 | B40: 0 | C40: 3 | D40: female | E40: 18 | F40: 2 | G40: 0 | H40: 18 | I40: S | J40: Third | K40: woman | L40: FALSE | N40: Southampton | O40: no | P40: FALSE
...

Sheet Train_Data
A1: Serial_Number | B1: pclass | C1: sex | D1: age | E1: sibsp | F1: parch | G1: fare | H1: embarked | I1: alone | J1: Actual | K1: Predicted | L1: Probability
A2: 693 | B2: 3 | C2: 1 | D2: 28 | E2: 0 | F2: 0 | G2: 56.4958 | H2: 2 | I2: TRUE | J2: 1 | K2: 1 | L2: 0.67048413
A3: 482 | B3: 2 | C3: 1 | D3: 28 | E3: 0 | F3: 0 | G3: 0 | H3: 2 | I3: TRUE | J3: 0 | K3: 0 | L3: 0
A4: 528 | B4: 1 | C4: 1 | D4: 28 | E4: 0 | F4: 0 | G4: 221.7792 | H4: 2 | I4: TRUE | J4: 0 | K4: 0 | L4: 0.098
A5: 856 | B5: 3 | C5: 0 | D5: 18 | E5: 0 | F5: 1 | G5: 9.35 | H5: 2 | I5: FALSE | J5: 1 | K5: 1 | L5: 0.76
A6: 802 | B6: 2 | C6: 0 | D6: 31 | E6: 1 | F6: 1 | G6: 26.25 | H6: 2 | I6: FALSE | J6: 1 | K6: 1 | L6: 0.99
A7: 653 | B7: 3 | C7: 1 | D7: 21 | E7: 0 | F7: 0 | G7: 8.4333 | H7: 2 | I7: TRUE | J7: 0 | K7: 0 | L7: 0.04
A8: 510 | B8: 3 | C8: 1 | D8: 26 | E8: 0 | F8: 0 | G8: 56.4958 | H8: 2 | I8: TRUE | J8: 1 | K8: 1 | L8: 0.88683333
A9: 558 | B9: 1 | C9: 1 | D9: 28 | E9: 0 | F9: 0 | G9: 227.525 | H9: 0 | I9: TRUE | J9: 0 | K9: 0 | L9: 0.04
A10: 829 | B10: 3 | C10: 1 | D10: 28 | E10: 0 | F10: 0 | G10: 7.75 | H10: 1 | I10: TRUE | J10: 1 | K10: 0 | L10: 0.30530952
A11: 19 | B11: 3 | C11: 0 | D11: 31 | E11: 1 | F11: 0 | G11: 18 | H11: 2 | I11: FALSE | J11: 0 | K11: 0 | L11: 0.32
A12: 648 | B12: 1 | C12: 1 | D12: 56 | E12: 0 | F12: 0 | G12: 35.5 | H12: 0 | I12: TRUE | J12: 1 | K12: 1 | L12: 0.65
A13: 403 | B13: 3 | C13: 0 | D13: 21 | E13: 1 | F13: 0 | G13: 9.825 | H13: 2 | I13: FALSE | J13: 0 | K13: 0 | L13: 0.06
... A713: 508 | B713: 1 | C713: 1 | D713: 28 | E713: 0 | F713: 0 | G713: 26.55 | H713: 2 | I713: TRUE | J713: 1 | K713: 1 | L713: 0.6498373

Sheet Test_Data
A1: Serial_Number | B1: pclass | C1: sex | D1: age | E1: sibsp | F1: parch | G1: fare | H1: embarked | I1: alone | J1: Actual | K1: Predicted | L1: Probability | M1: survived
A2: 566 | B2: 3 | C2: 1 | D2: 24 | E2: 2 | F2: 0 | G2: 24.15 | H2: 2 | I2: FALSE | J2: 0 | K2: 0 | L2: 0.32 | M2: =VLOOKUP(A2,Raw_Data!$A$2:$L$892,2,FALSE) -> 0
A3: 161 | B3: 3 | C3: 1 | D3: 44 | E3: 0 | F3: 1 | G3: 16.1 | H3: 2 | I3: FALSE | J3: 0 | K3: 0 | L3: 0.14 | M3: =VLOOKUP(A3,Raw_Data!$A$2:$L$892,2,FALSE) -> 0
A4: 554 | B4: 3 | C4: 1 | D4: 22 | E4: 0 | F4: 0 | G4: 7.225 | H4: 0 | I4: TRUE | J4: 1 | K4: 0 | L4: 0.08 | M4: =VLOOKUP(A4,Raw_Data!$A$2:$L$892,2,FALSE) -> 1
A5: 861 | B5: 3 | C5: 1 | D5: 41 | E5: 2 | F5: 0 | G5: 14.1083 | H5: 2 | I5: FALSE | J5: 0 | K5: 0 | L5: 0.03 | M5: =VLOOKUP(A5,Raw_Data!$A$2:$L$892,2,FALSE) -> 0
A6: 242 | B6: 3 | C6: 0 | D6: 28 | E6: 1 | F6: 0 | G6: 15.5 | H6: 1 | I6: FALSE | J6: 1 | K6: 1 | L6: 0.78 | M6: =VLOOKUP(A6,Raw_Data!$A$2:$L$892,2,FALSE) -> 1
A7: 560 | B7: 3 | C7: 0 | D7: 36 | E7: 1 | F7: 0 | G7: 17.4 | H7: 2 | I7: FALSE | J7: 1 | K7: 0 | L7: 0.3 | M7: =VLOOKUP(A7,Raw_Data!$A$2:$L$892,2,FALSE) -> 1
A8: 388 | B8: 2 | C8: 0 | D8: 36 | E8: 0 | F8: 0 | G8: 13 | H8: 2 | I8: TRUE | J8: 1 | K8: 1 | L8: 0.83 | M8: =VLOOKUP(A8,Raw_Data!$A$2:$L$892,2,FALSE) -> 1
A9: 537 | B9: 1 | C9: 1 | D9: 45 | E9: 0 | F9: 0 | G9: 26.55 | H9: 2 | I9: TRUE | J9: 0 | K9: 1 | L9: 0.77 | M9: =VLOOKUP(A9,Raw_Data!$A$2:$L$892,2,FALSE) -> 0
A10: 699 | B10: 1 | C10: 1 | D10: 49 | E10: 1 | F10: 1 | G10: 110.8833 | H10: 0 | I10: FALSE | J10: 0 | K10: 1 | L10: 0.54 | M10: =VLOOKUP(A10,Raw_Data!$A$2:$L$892,2,FALSE) -> 0
A11: 100 | B11: 2 | C11: 1 | D11: 34 | E11: 1 | F11: 0 | G11: 26 | H11: 2 | I11: FALSE | J11: 0 | K11: 0 | L11: 0.37 | M11: =VLOOKUP(A11,Raw_Data!$A$2:$L$892,2,FALSE) -> 0
A12: 127 | B12: 3 | C12: 1 | D12: 28 | E12: 0 | F12: 0 | G12: 7.75 | H12: 1 | I12: TRUE | J12: 0 | K12: 0 | L12: 0.30530952 | M12: =VLOOKUP(A12,Raw_Data!$A$2:$L$892,2,FALSE) -> 0
A13: 334 | B13: 3 | C13: 1 | D13: 16 | E13: 2 | F13: 0 | G13: 18 | H13: 2 | I13: FALSE | J13: 0 | K13: 0 | L13: 0.28 | M13: =VLOOKUP(A13,Raw_Data!$A$2:$L$892,2,FALSE) -> 0
... A180: 638 | B180: 2 | C180: 1 | D180: 31 | E180: 1 | F180: 1 | G180: 26.25 | H180: 2 | I180: FALSE | J180: 0 | K180: 0 | L180: 0.21 | M180: =VLOOKUP(A180,Raw_Data!$A$2:$L$892,2,FALSE) -> 0

Sheet Confusion_Matrix
B1: Predicted_0 | C1: Predicted_1 | E1: survived | F1: Predicted
A2: Actual_0 | B2: 96 | C2: 14 | E2: 0 | F2: 0
A3: Actual_1 | B3: 18 | C3: 51 | E3: 0 | F3: 0
E4: 1 | F4: 0
E5: 0 | F5: 0
C6: predicted | E6: 1 | F6: 1
C7: 1 | D7: 0 | E7: 1 | F7: 0
A8: Actual | B8: 1 | C8: =COUNTIFS($E$2:$E$180,$B8,$F$2:$F$180,C$7) -> 51 | D8: =COUNTIFS($E$2:$E$180,$B8,$F$2:$F$180,D$7) -> 18 | E8: 1 | F8: 1
B9: 0 | C9: =COUNTIFS($E$2:$E$180,$B9,$F$2:$F$180,C$7) -> 14 | D9: =COUNTIFS($E$2:$E$180,$B9,$F$2:$F$180,D$7) -> 96 | E9: 0 | F9: 1
E10: 0 | F10: 1
E11: 0 | F11: 0
E12: 0 | F12: 0
E13: 0 | F13: 0
E14: 1 | F14: 1
E15: 0 | F15: 0
E16: 0 | F16: 0
E17: 0 | F17: 0
E18: 0 | F18: 0
E19: 0 | F19: 0
E20: 0 | F20: 0
E21: 1 | F21: 1
... E180: 0 | F180: 0

Sheet Model_Evaluation
A1: Metric | B1: Value
A2: Accuracy | B2: 0.82122905
A3: Precision | B3: 0.78461538
A4: Recall | B4: 0.73913043
A5: F1 Score | B5: 0.76119403
A6: False Positive Rate | B6: 0.12727273
A7: True Positive Rate | B7: 0.73913043
A8: ROC-AUC | B8: 0.83267457

Sheet ROC_Curve_Data
A1: FPR | B1: TPR | C1: Threshold
A2: 0 | B2: 0 | C2: inf
A3: 0 | B3: 0.028985507 | C3: 1
A4: 0 | B4: 0.043478261 | C4: 0.99
A5: 0 | B5: 0.072463768 | C5: 0.98
A6: 0 | B6: 0.11594203 | C6: 0.95694444
A7: 0.018181818 | B7: 0.11594203 | C7: 0.95
A8: 0.018181818 | B8: 0.14492754 | C8: 0.93
A9: 0.018181818 | B9: 0.17391304 | C9: 0.92
A10: 0.018181818 | B10: 0.26086957 | C10: 0.89
A11: 0.018181818 | B11: 0.27536232 | C11: 0.88
A12: 0.018181818 | B12: 0.30434783 | C12: 0.87891478
A13: 0.018181818 | B13: 0.34782609 | C13: 0.87
A14: 0.018181818 | B14: 0.36231884 | C14: 0.85717546
... A77: 1 | B77: 1 | C77: 0
